<mujoco model="mutiagent_world">
  <compiler angle="degree" coordinate="local" inertiafromgeom="true" />
  <option integrator="RK4" timestep="0.003" solver="PGS" iterations="1000" />
  <default>
    <joint armature="1" damping="1" limited="true" />
  <default class="agent0"><joint armature="1" damping="1" limited="true" />
    <geom conaffinity="0" condim="3" density="5.0" friction="1 0.5 0.5" margin="0.01" rgba="0.98 0.87 0.67 1" material="geom" contype="1" />
  </default><default class="agent1"><joint armature="1" damping="1" limited="true" />
    <geom conaffinity="1" condim="3" density="5.0" friction="1 0.5 0.5" margin="0.01" rgba="0.98 0.87 0.67 1" material="geom" contype="0" />
  </default></default>
  <visual>
    <headlight ambient=".1 .1 .1" diffuse=".6 .6 .6" specular="0.3 0.3 0.3" />
    <map znear=".01" />
    <quality shadowsize="16384" />
  </visual>
  <asset>
    <texture builtin="gradient" height="100" rgb1="1 1 1" rgb2="0 0 0" type="skybox" width="100" />
    <texture builtin="flat" height="1278" mark="cross" markrgb="0 0 0" name="texgeom" random="0.01" rgb1="0.8 0.6 0.4" rgb2="0.8 0.6 0.4" type="cube" width="127" />
    <texture builtin="checker" height="100" name="texplane" rgb1="0.5 0.5 0.5" rgb2="0.5 0.5 0.5" type="2d" width="100" markrgb="0.2 0.2 0.2" mark="edge" />
    <texture name="MatPlane" type="2d" builtin="checker" rgb1=".5 .5 .5" rgb2=".5 .5 .5" width="300" height="300" mark="edge" markrgb="0.1 0.1 0.1" />
    <material name="MatPlane" texture="MatPlane" texrepeat="2 2" texuniform="true" reflectance=".2" />
    <material name="geom" texture="texgeom" texuniform="true" />
  </asset>
  <worldbody>
    <light cutoff="100" diffuse="1 1 1" dir="-0 0 -1.3" directional="true" exponent="1" pos="0 0 1.3" specular=".1 .1 .1" />
    <geom contype="1" conaffinity="1" friction="1 .1 .1" condim="3" material="MatPlane" name="floor" pos="0 0 0" rgba="1 1 1 1" size="20 20 0.125" type="plane" />
    <geom fromto="4 -5 0  4 +5 0" name="rightgoal" rgba="0.6 0.0 0.0 0" size=".03" type="cylinder" />
    <geom fromto="-4 -5 0  -4 +5 0" name="leftgoal" rgba="0.6 0.0 0.0 0" size=".03" type="cylinder" />
    <geom conaffinity="1" condim="3" contype="1" friction="1 .1 .1" name="arena" size="4.5 .25" type="cylinder" pos="0 0 0.25" rgba="0.3 0.3 0.3 1" />
  <body name="agent0/0" pos="-1 0 1.5" euler="0 0 0">
    <geom pos="0 0 0" size="0.25" type="sphere" class="agent0" name="agent0/anon3617693704" />
    <joint armature="0" damping="0" limited="false" margin="0.01" name="agent0/0_joint" pos="0 0 0" range="-30 30" type="free" />
    <body name="agent0/1" pos="0 0 0">
      <geom fromto="0 0 0 0.2 0.2 0" size="0.08" type="capsule" class="agent0" name="agent0/anon8501003736" />
      <body name="agent0/11" pos="0.2 0.2 0">
        <joint axis="0 0 1" name="agent0/11_joint" pos="0 0 0" range="-30 30" type="hinge" />
        <geom fromto="0.0 0.0 0.0 0.2 0.2 0.0" size="0.08" type="capsule" class="agent0" name="agent0/anon2163050540" />
        <body name="agent0/111" pos="0.2 0.2 0">
          <geom fromto="0 0 0 0.4 0.4 0" size="0.08" type="capsule" class="agent0" name="agent0/anon9667682704" />
          <joint axis="-0.707107 0.707107 0" name="agent0/111_joint" pos="0 0 0" range="30 70" type="hinge" />
        </body>
      </body>
    </body>
    <body name="agent0/2" pos="0 0 0">
      <geom fromto="0 0 0 -0.2 0.2 0" size="0.08" type="capsule" class="agent0" name="agent0/anon6526899510" />
      <body name="agent0/12" pos="-0.2 0.2 0">
        <joint axis="0 0 1" name="agent0/12_joint" pos="0 0 0" range="-30 30" type="hinge" />
        <geom fromto="0.0 0.0 0.0 -0.2 0.2 0.0" size="0.08" type="capsule" class="agent0" name="agent0/anon2336117160" />
        <body name="agent0/112" pos="-0.2 0.2 0">
          <geom fromto="0 0 0 -0.4 0.4 0" size="0.08" type="capsule" class="agent0" name="agent0/anon7803232127" />
          <joint axis="-0.707107 -0.707107 0" name="agent0/112_joint" pos="0 0 0" range="30 70" type="hinge" />
        </body>
      </body>
    </body>

    <body name="agent0/3" pos="0 0 0">
      <geom fromto="0 0 0 -0.2 -0.2 0" size="0.08" type="capsule" class="agent0" name="agent0/anon6525082215" />
      <body name="agent0/13" pos="-0.2 -0.2 0">
        <joint axis="0 0 1" name="agent0/13_joint" pos="0 0 0" range="-30 30" type="hinge" />
        <geom fromto="0 0 0 -0.2 -0.2 0" size="0.08" type="capsule" class="agent0" name="agent0/anon9493545235" />
        <body name="agent0/113" pos="-0.2 -0.2 0">
          <geom fromto="0 0 0 -0.4 -0.4 0" size="0.08" type="capsule" class="agent0" name="agent0/anon3540309144" />
          <joint axis="0.707107 -0.707107 0" name="agent0/113_joint" pos="0 0 0" range="30 70" type="hinge" />
        </body>
      </body>
    </body>

    <body name="agent0/4" pos="0 0 0">
      <geom fromto="0 0 0 0.2 -0.2 0" size="0.08" type="capsule" class="agent0" name="agent0/anon7540222680" />
      <body name="agent0/14" pos="0.2 -0.2 0">
        <joint axis="0 0 1" name="agent0/14_joint" pos="0 0 0" range="-30 30" type="hinge" />
        <geom fromto="0 0 0 0.2 -0.2 0" size="0.08" type="capsule" class="agent0" name="agent0/anon5240591656" />
        <body name="agent0/114" pos="0.2 -0.2 0">
          <geom fromto="0 0 0 0.4 -0.4 0" size="0.08" type="capsule" class="agent0" name="agent0/anon4714348348" />
          <joint axis="0.707107 0.707107 0" name="agent0/114_joint" pos="0 0 0" range="30 70" type="hinge" />
        </body>
      </body>
    </body>
  </body>
  

  <body name="agent1/0" pos="1 0 1.5" euler="0 0 180">
    <geom pos="0 0 0" size="0.25" type="sphere" class="agent1" name="agent1/anon2306549595" />
    <joint armature="0" damping="0" limited="false" margin="0.01" name="agent1/0_joint" pos="0 0 0" range="-30 30" type="free" />
    <body name="agent1/1" pos="0 0 0">
      <geom fromto="0 0 0 0.2 0.2 0" size="0.08" type="capsule" class="agent1" name="agent1/anon621807675" />
      <body name="agent1/11" pos="0.2 0.2 0">
        <joint axis="0 0 1" name="agent1/11_joint" pos="0 0 0" range="-30 30" type="hinge" />
        <geom fromto="0.0 0.0 0.0 0.2 0.2 0.0" size="0.08" type="capsule" class="agent1" name="agent1/anon4236525270" />
        <body name="agent1/111" pos="0.2 0.2 0">
          <geom fromto="0 0 0 0.4 0.4 0" size="0.08" type="capsule" class="agent1" name="agent1/anon4067024635" />
          <joint axis="-0.707107 0.707107 0" name="agent1/111_joint" pos="0 0 0" range="30 70" type="hinge" />
        </body>
      </body>
    </body>
    <body name="agent1/2" pos="0 0 0">
      <geom fromto="0 0 0 -0.2 0.2 0" size="0.08" type="capsule" class="agent1" name="agent1/anon4440969505" />
      <body name="agent1/12" pos="-0.2 0.2 0">
        <joint axis="0 0 1" name="agent1/12_joint" pos="0 0 0" range="-30 30" type="hinge" />
        <geom fromto="0.0 0.0 0.0 -0.2 0.2 0.0" size="0.08" type="capsule" class="agent1" name="agent1/anon6436148966" />
        <body name="agent1/112" pos="-0.2 0.2 0">
          <geom fromto="0 0 0 -0.4 0.4 0" size="0.08" type="capsule" class="agent1" name="agent1/anon5131287312" />
          <joint axis="-0.707107 -0.707107 0" name="agent1/112_joint" pos="0 0 0" range="30 70" type="hinge" />
        </body>
      </body>
    </body>

    <body name="agent1/3" pos="0 0 0">
      <geom fromto="0 0 0 -0.2 -0.2 0" size="0.08" type="capsule" class="agent1" name="agent1/anon260589467" />
      <body name="agent1/13" pos="-0.2 -0.2 0">
        <joint axis="0 0 1" name="agent1/13_joint" pos="0 0 0" range="-30 30" type="hinge" />
        <geom fromto="0 0 0 -0.2 -0.2 0" size="0.08" type="capsule" class="agent1" name="agent1/anon5945875729" />
        <body name="agent1/113" pos="-0.2 -0.2 0">
          <geom fromto="0 0 0 -0.4 -0.4 0" size="0.08" type="capsule" class="agent1" name="agent1/anon4309234531" />
          <joint axis="0.707107 -0.707107 0" name="agent1/113_joint" pos="0 0 0" range="30 70" type="hinge" />
        </body>
      </body>
    </body>

    <body name="agent1/4" pos="0 0 0">
      <geom fromto="0 0 0 0.2 -0.2 0" size="0.08" type="capsule" class="agent1" name="agent1/anon8919721462" />
      <body name="agent1/14" pos="0.2 -0.2 0">
        <joint axis="0 0 1" name="agent1/14_joint" pos="0 0 0" range="-30 30" type="hinge" />
        <geom fromto="0 0 0 0.2 -0.2 0" size="0.08" type="capsule" class="agent1" name="agent1/anon4375121794" />
        <body name="agent1/114" pos="0.2 -0.2 0">
          <geom fromto="0 0 0 0.4 -0.4 0" size="0.08" type="capsule" class="agent1" name="agent1/anon306977276" />
          <joint axis="0.707107 0.707107 0" name="agent1/114_joint" pos="0 0 0" range="30 70" type="hinge" />
        </body>
      </body>
    </body>
  </body>
  

  </worldbody>
<actuator>
    <motor ctrllimited="true" ctrlrange="-1.0 1.0" joint="agent0/11_joint" gear="150" name="agent0/11_joint" class="agent0" />
    <motor ctrllimited="true" ctrlrange="-1.0 1.0" joint="agent0/12_joint" gear="150" name="agent0/12_joint" class="agent0" />
    <motor ctrllimited="true" ctrlrange="-1.0 1.0" joint="agent0/13_joint" gear="150" name="agent0/13_joint" class="agent0" />
    <motor ctrllimited="true" ctrlrange="-1.0 1.0" joint="agent0/14_joint" gear="150" name="agent0/14_joint" class="agent0" />
    <motor ctrllimited="true" ctrlrange="-1.0 1.0" joint="agent0/111_joint" gear="150" name="agent0/111_joint" class="agent0" />
    <motor ctrllimited="true" ctrlrange="-1.0 1.0" joint="agent0/112_joint" gear="150" name="agent0/112_joint" class="agent0" />
    <motor ctrllimited="true" ctrlrange="-1.0 1.0" joint="agent0/113_joint" gear="150" name="agent0/113_joint" class="agent0" />
    <motor ctrllimited="true" ctrlrange="-1.0 1.0" joint="agent0/114_joint" gear="150" name="agent0/114_joint" class="agent0" />
  <motor ctrllimited="true" ctrlrange="-1.0 1.0" joint="agent1/11_joint" gear="150" name="agent1/11_joint" class="agent1" />
    <motor ctrllimited="true" ctrlrange="-1.0 1.0" joint="agent1/12_joint" gear="150" name="agent1/12_joint" class="agent1" />
    <motor ctrllimited="true" ctrlrange="-1.0 1.0" joint="agent1/13_joint" gear="150" name="agent1/13_joint" class="agent1" />
    <motor ctrllimited="true" ctrlrange="-1.0 1.0" joint="agent1/14_joint" gear="150" name="agent1/14_joint" class="agent1" />
    <motor ctrllimited="true" ctrlrange="-1.0 1.0" joint="agent1/111_joint" gear="150" name="agent1/111_joint" class="agent1" />
    <motor ctrllimited="true" ctrlrange="-1.0 1.0" joint="agent1/112_joint" gear="150" name="agent1/112_joint" class="agent1" />
    <motor ctrllimited="true" ctrlrange="-1.0 1.0" joint="agent1/113_joint" gear="150" name="agent1/113_joint" class="agent1" />
    <motor ctrllimited="true" ctrlrange="-1.0 1.0" joint="agent1/114_joint" gear="150" name="agent1/114_joint" class="agent1" />
  </actuator>
  </mujoco>