<mujoco model="mutiagent_world">
  <compiler angle="degree" coordinate="local" inertiafromgeom="true" />
  <option integrator="RK4" timestep="0.003" solver="PGS" iterations="1000" />
  <default>
    <joint armature="1" damping="1" limited="true" />
  <default class="agent0"><joint armature="1" damping="1" limited="true" />
    <geom conaffinity="0" condim="3" density="5.0" friction="1 0.5 0.5" margin="0.01" rgba="0.98 0.87 0.67 1" material="geom" contype="1" />
    <motor ctrllimited="true" ctrlrange="-.4 .4" />
</default><default class="agent1"><geom conaffinity="1" condim="3" density="5.0" friction="1 0.5 0.5" margin="0.01" rgba="0.98 0.87 0.67 1" material="geom" contype="0" />
    <motor ctrllimited="true" ctrlrange="-1. 1." />
  </default></default>
  <visual>
    <headlight ambient=".1 .1 .1" diffuse=".6 .6 .6" specular="0.3 0.3 0.3" />
    <map znear=".01" />
    <quality shadowsize="16384" />
  </visual>
  <asset>
    <texture builtin="gradient" height="100" rgb1="1 1 1" rgb2="0 0 0" type="skybox" width="100" />
    <texture builtin="flat" height="1278" mark="cross" markrgb="0 0 0" name="texgeom" random="0.01" rgb1="0.8 0.6 0.4" rgb2="0.8 0.6 0.4" type="cube" width="127" />
    <texture builtin="checker" height="100" name="texplane" rgb1="0.5 0.5 0.5" rgb2="0.5 0.5 0.5" type="2d" width="100" markrgb="0.2 0.2 0.2" mark="edge" />
    <texture name="MatPlane" type="2d" builtin="checker" rgb1=".5 .5 .5" rgb2=".5 .5 .5" width="300" height="300" mark="edge" markrgb="0.1 0.1 0.1" />
    <material name="MatPlane" texture="MatPlane" texrepeat="2 2" texuniform="true" reflectance=".2" />
    <material name="geom" texture="texgeom" texuniform="true" />
  </asset>
  <worldbody>
    <light cutoff="100" diffuse="1 1 1" dir="-0 0 -1.3" directional="true" exponent="1" pos="0 0 1.3" specular=".1 .1 .1" />
    <geom contype="1" conaffinity="1" friction="1 .1 .1" condim="3" material="MatPlane" name="floor" pos="0 0 0" rgba="1 1 1 1" size="20 20 0.125" type="plane" />
    <geom fromto="4 -5 0  4 +5 0" name="rightgoal" rgba="0.6 0.0 0.0 0" size=".03" type="cylinder" />
    <geom fromto="-4 -5 0  -4 +5 0" name="leftgoal" rgba="0.6 0.0 0.0 0" size=".03" type="cylinder" />
    <geom conaffinity="1" condim="3" contype="1" friction="1 .1 .1" name="arena" size="4.5 .25" type="cylinder" pos="0 0 0.25" rgba="0.3 0.3 0.3 1" />
  <body name="agent0/torso" pos="-1 0 1.5" euler="0 0 0">
  <geom name="agent0/torso_geom" pos="0 0 0" size="0.25" type="sphere" class="agent0" />
  <joint armature="0" damping="0" limited="false" margin="0.01" name="agent0/root" pos="0 0 0" range="-30 30" type="free" />
  <body name="agent0/front_left_leg" pos="0 0 0">
    <geom fromto="0.0 0.0 0.0 0.2 0.2 0.0" name="agent0/aux_1_geom" size="0.08" type="capsule" class="agent0" />
    <body name="agent0/aux_1" pos="0.2 0.2 0">
      <joint axis="0 0 1" name="agent0/hip_1" pos="0.0 0.0 0.0" range="-30 30" type="hinge" />
      <geom fromto="0.0 0.0 0.0 0.2 0.2 0.0" name="agent0/left_leg_geom" size="0.08" type="capsule" class="agent0" />
      <body pos="0.2 0.2 0" name="agent0/anon787846415">
        <joint axis="-1 1 0" name="agent0/ankle_1" pos="0.0 0.0 0.0" range="30 70" type="hinge" />
        <geom fromto="0.0 0.0 0.0 0.4 0.4 0.0" name="agent0/left_ankle_geom" size="0.08" type="capsule" class="agent0" />
      </body>
    </body>
  </body>
  <body name="agent0/front_right_leg" pos="0 0 0">
    <geom fromto="0.0 0.0 0.0 -0.2 0.2 0.0" name="agent0/aux_2_geom" size="0.08" type="capsule" class="agent0" />
    <body name="agent0/aux_2" pos="-0.2 0.2 0">
      <joint axis="0 0 1" name="agent0/hip_2" pos="0.0 0.0 0.0" range="-30 30" type="hinge" />
      <geom fromto="0.0 0.0 0.0 -0.2 0.2 0.0" name="agent0/right_leg_geom" size="0.08" type="capsule" class="agent0" />
      <body pos="-0.2 0.2 0" name="agent0/anon2563451925">
        <joint axis="1 1 0" name="agent0/ankle_2" pos="0.0 0.0 0.0" range="-70 -30" type="hinge" />
        <geom fromto="0.0 0.0 0.0 -0.4 0.4 0.0" name="agent0/right_ankle_geom" size="0.08" type="capsule" class="agent0" />
      </body>
    </body>
  </body>
  <body name="agent0/back_leg" pos="0 0 0">
    <geom fromto="0.0 0.0 0.0 -0.2 -0.2 0.0" name="agent0/aux_3_geom" size="0.08" type="capsule" class="agent0" />
    <body name="agent0/aux_3" pos="-0.2 -0.2 0">
      <joint axis="0 0 1" name="agent0/hip_3" pos="0.0 0.0 0.0" range="-30 30" type="hinge" />
      <geom fromto="0.0 0.0 0.0 -0.2 -0.2 0.0" name="agent0/back_leg_geom" size="0.08" type="capsule" class="agent0" />
      <body pos="-0.2 -0.2 0" name="agent0/anon9019323607">
        <joint axis="-1 1 0" name="agent0/ankle_3" pos="0.0 0.0 0.0" range="-70 -30" type="hinge" />
        <geom fromto="0.0 0.0 0.0 -0.4 -0.4 0.0" name="agent0/third_ankle_geom" size="0.08" type="capsule" class="agent0" />
      </body>
    </body>
  </body>
  <body name="agent0/right_back_leg" pos="0 0 0">
    <geom fromto="0.0 0.0 0.0 0.2 -0.2 0.0" name="agent0/aux_4_geom" size="0.08" type="capsule" class="agent0" />
    <body name="agent0/aux_4" pos="0.2 -0.2 0">
      <joint axis="0 0 1" name="agent0/hip_4" pos="0.0 0.0 0.0" range="-30 30" type="hinge" />
      <geom fromto="0.0 0.0 0.0 0.2 -0.2 0.0" name="agent0/rightback_leg_geom" size="0.08" type="capsule" class="agent0" />
      <body pos="0.2 -0.2 0" name="agent0/anon4537253173">
        <joint axis="1 1 0" name="agent0/ankle_4" pos="0.0 0.0 0.0" range="30 70" type="hinge" />
        <geom fromto="0.0 0.0 0.0 0.4 -0.4 0.0" name="agent0/fourth_ankle_geom" size="0.08" type="capsule" class="agent0" />
      </body>
    </body>
  </body>
</body>


<body name="agent1/torso" pos="1 0 1.5">
    <geom name="agent1/torso_geom" pos="0 0 0" size="0.25" type="sphere" class="agent1" />
    <joint armature="0" damping="0" limited="false" margin="0.01" name="agent1/root" pos="0 0 0" type="free" />
    
    <body name="agent1/back_right_leg" pos="0 0 0">
      <geom density="5.0" fromto="0 0 0 -0.056 0.209 0.125" name="agent1/aux_1_geom" size="0.04" type="capsule" class="agent1" />
      <body name="agent1/aux_11" pos="-0.056 0.209 0.125">
        <joint axis="0 0 1" name="agent1/hip_1" pos="0 0 0" range="-20 20" type="hinge" />
        <geom density="5.0" fromto="0 0 0 -0.050 0.188 0.113" name="agent1/back_right_leg_geom" size="0.04" type="capsule" class="agent1" />
        <body name="agent1/aux_12" pos="-0.050 0.188 0.113">
          <joint axis="0.97 0.26 0" name="agent1/ankle_1" pos="0 0 0" range="-35 45" type="hinge" />
          <geom density="5.0" fromto="0 0 0 -0.112 0.418 -0.600" name="agent1/back_right_ankle_geom" size="0.04" type="capsule" class="agent1" />
        </body>
      </body>
    </body>
    
    <body name="agent1/back_left_leg" pos="0 0 0">
      <geom density="5.0" fromto="0 0 0 0.056 0.209 0.125" name="agent1/aux_2_geom" size="0.04" type="capsule" class="agent1" />
      <body name="agent1/aux_21" pos="0.056 0.209 0.125">
        <joint axis="0 0 1" name="agent1/hip_2" pos="0 0 0" range="-20 20" type="hinge" />
        <geom density="5.0" fromto="0 0 0 0.050 0.188 0.113" name="agent1/back_left_leg_geom" size="0.04" type="capsule" class="agent1" />
        <body name="agent1/aux_22" pos="0.050 0.188 0.113">
          <joint axis="-0.97 0.26 0" name="agent1/ankle_2" pos="0 0 0" range="-45 35" type="hinge" />
          <geom density="5.0" fromto="0 0 0 0.112 0.418 -0.600" name="agent1/back_left_ankle_geom" size="0.04" type="capsule" class="agent1" />
        </body>
      </body>
    </body>
    
    <body name="agent1/middle_back_right_leg" pos="0 0 0">
      <geom density="5.0" fromto="0 0 0 -0.188 0.108 0.125" name="agent1/aux_3_geom" size="0.04" type="capsule" class="agent1" />
      <body name="agent1/aux_31" pos="-0.188 0.108 0.125">
        <joint axis="0 0 1" name="agent1/hip_3" pos="0 0 0" range="-20 20" type="hinge" />
        <geom density="5.0" fromto="0 0 0 -0.170 0.097 0.113" name="agent1/middle_back_right_leg_geom" size="0.04" type="capsule" class="agent1" />
        <body name="agent1/aux_32" pos="-0.170 0.097 0.113">
          <joint axis="0.50 0.87 0" name="agent1/ankle_3" pos="0 0 0" range="-35 45" type="hinge" />
          <geom density="5.0" fromto="0 0 0 -0.376 0.216 -0.600" name="agent1/middle_back_right_ankle_geom" size="0.04" type="capsule" class="agent1" />
        </body>
      </body>
    </body>
    
    <body name="agent1/middle_back_left_leg" pos="0 0 0">
      <geom density="5.0" fromto="0 0 0 0.188 0.108 0.125" name="agent1/aux_4_geom" size="0.04" type="capsule" class="agent1" />
      <body name="agent1/aux_41" pos="0.188 0.108 0.125">
        <joint axis="0 0 1" name="agent1/hip_4" pos="0 0 0" range="-20 20" type="hinge" />
        <geom density="5.0" fromto="0 0 0 0.170 0.097 0.113" name="agent1/middle_back_left_leg_geom" size="0.04" type="capsule" class="agent1" />
        <body name="agent1/aux_42" pos="0.170 0.097 0.113">
          <joint axis="-0.50 0.87 0" name="agent1/ankle_4" pos="0 0 0" range="-45 35" type="hinge" />
          <geom density="5.0" fromto="0 0 0 0.376 0.216 -0.600" name="agent1/middle_back_left_ankle_geom" size="0.04" type="capsule" class="agent1" />
        </body>
      </body>
    </body>
    
    <body name="agent1/middle_front_right_leg" pos="0 0 0">
      <geom density="5.0" fromto="0 0 0 -0.209 -0.056 0.125" name="agent1/aux_5_geom" size="0.04" type="capsule" class="agent1" />
      <body name="agent1/aux_51" pos="-0.209 -0.056 0.125">
        <joint axis="0 0 1" name="agent1/hip_5" pos="0 0 0" range="-20 20" type="hinge" />
        <geom density="5.0" fromto="0 0 0 -0.188 -0.050 0.113" name="agent1/middle_front_right_leg_geom" size="0.04" type="capsule" class="agent1" />
        <body name="agent1/aux_52" pos="-0.188 -0.050 0.113">
          <joint axis="-0.26 0.97 0" name="agent1/ankle_5" pos="0 0 0" range="-35 45" type="hinge" />
          <geom density="5.0" fromto="0 0 0 -0.418 -0.112 -0.600" name="agent1/middle_front_right_ankle_geom" size="0.04" type="capsule" class="agent1" />
        </body>
      </body>
    </body>
    
    <body name="agent1/middle_front_left_leg" pos="0 0 0">
      <geom density="5.0" fromto="0 0 0 0.209 -0.056 0.125" name="agent1/aux_6_geom" size="0.04" type="capsule" class="agent1" />
      <body name="agent1/aux_61" pos="0.209 -0.056 0.125">
        <joint axis="0 0 1" name="agent1/hip_6" pos="0 0 0" range="-20 20" type="hinge" />
        <geom density="5.0" fromto="0 0 0 0.188 -0.050 0.113" name="agent1/middle_front_left_leg_geom" size="0.04" type="capsule" class="agent1" />
        <body name="agent1/aux_62" pos="0.188 -0.050 0.113">
          <joint axis="0.26 0.97 0" name="agent1/ankle_6" pos="0 0 0" range="-45 35" type="hinge" />
          <geom density="5.0" fromto="0 0 0 0.418 -0.112 -0.600" name="agent1/middle_front_left_ankle_geom" size="0.04" type="capsule" class="agent1" />
        </body>
      </body>
    </body>
    
    <body name="agent1/front_right_leg" pos="0 0 0">
      <geom density="5.0" fromto="0 0 0 -0.108 -0.188 0.125" name="agent1/aux_7_geom" size="0.04" type="capsule" class="agent1" />
      <body name="agent1/aux_71" pos="-0.108 -0.188 0.125">
        <joint axis="0 0 1" name="agent1/hip_7" pos="0 0 0" range="-20 20" type="hinge" />
        <geom density="5.0" fromto="0 0 0 -0.097 -0.170 0.113" name="agent1/front_right_leg_geom" size="0.04" type="capsule" class="agent1" />
        <body name="agent1/aux_72" pos="-0.097 -0.170 0.113">
          <joint axis="-0.87 0.50 0" name="agent1/ankle_7" pos="0 0 0" range="-35 45" type="hinge" />
          <geom density="5.0" fromto="0 0 0 -0.216 -0.376 -0.600" name="agent1/front_right_ankle_geom" size="0.04" type="capsule" class="agent1" />
        </body>
      </body>
    </body>
    
    <body name="agent1/front_left_leg" pos="0 0 0">
      <geom density="5.0" fromto="0 0 0 0.108 -0.188 0.125" name="agent1/aux_8_geom" size="0.04" type="capsule" class="agent1" />
      <body name="agent1/aux_81" pos="0.108 -0.188 0.125">
        <joint axis="0 0 1" name="agent1/hip_8" pos="0 0 0" range="-20 20" type="hinge" />
        <geom density="5.0" fromto="0 0 0 0.097 -0.170 0.113" name="agent1/front_left_leg_geom" size="0.04" type="capsule" class="agent1" />
        <body name="agent1/aux_82" pos="0.097 -0.170 0.113">
          <joint axis="0.87 0.50 0" name="agent1/ankle_8" pos="0 0 0" range="-45 35" type="hinge" />
          <geom density="5.0" fromto="0 0 0 0.216 -0.376 -0.600" name="agent1/front_left_ankle_geom" size="0.04" type="capsule" class="agent1" />
        </body>
      </body>
    </body>
  </body>
  </worldbody>
<actuator>
  <motor ctrllimited="true" ctrlrange="-1.0 1.0" joint="agent0/hip_4" gear="150" class="agent0" />
  <motor ctrllimited="true" ctrlrange="-1.0 1.0" joint="agent0/ankle_4" gear="150" class="agent0" />
  <motor ctrllimited="true" ctrlrange="-1.0 1.0" joint="agent0/hip_1" gear="150" class="agent0" />
  <motor ctrllimited="true" ctrlrange="-1.0 1.0" joint="agent0/ankle_1" gear="150" class="agent0" />
  <motor ctrllimited="true" ctrlrange="-1.0 1.0" joint="agent0/hip_2" gear="150" class="agent0" />
  <motor ctrllimited="true" ctrlrange="-1.0 1.0" joint="agent0/ankle_2" gear="150" class="agent0" />
  <motor ctrllimited="true" ctrlrange="-1.0 1.0" joint="agent0/hip_3" gear="150" class="agent0" />
  <motor ctrllimited="true" ctrlrange="-1.0 1.0" joint="agent0/ankle_3" gear="150" class="agent0" />
<motor ctrllimited="true" ctrlrange="-1.0 1.0" joint="agent1/hip_1" gear="150" class="agent1" />
    <motor ctrllimited="true" ctrlrange="-1.0 1.0" joint="agent1/ankle_1" gear="150" class="agent1" />
    <motor ctrllimited="true" ctrlrange="-1.0 1.0" joint="agent1/hip_2" gear="150" class="agent1" />
    <motor ctrllimited="true" ctrlrange="-1.0 1.0" joint="agent1/ankle_2" gear="150" class="agent1" />
    <motor ctrllimited="true" ctrlrange="-1.0 1.0" joint="agent1/hip_3" gear="150" class="agent1" />
    <motor ctrllimited="true" ctrlrange="-1.0 1.0" joint="agent1/ankle_3" gear="150" class="agent1" />
    <motor ctrllimited="true" ctrlrange="-1.0 1.0" joint="agent1/hip_4" gear="150" class="agent1" />
    <motor ctrllimited="true" ctrlrange="-1.0 1.0" joint="agent1/ankle_4" gear="150" class="agent1" />
    <motor ctrllimited="true" ctrlrange="-1.0 1.0" joint="agent1/hip_5" gear="150" class="agent1" />
    <motor ctrllimited="true" ctrlrange="-1.0 1.0" joint="agent1/ankle_5" gear="150" class="agent1" />
    <motor ctrllimited="true" ctrlrange="-1.0 1.0" joint="agent1/hip_6" gear="150" class="agent1" />
    <motor ctrllimited="true" ctrlrange="-1.0 1.0" joint="agent1/ankle_6" gear="150" class="agent1" />
    <motor ctrllimited="true" ctrlrange="-1.0 1.0" joint="agent1/hip_7" gear="150" class="agent1" />
    <motor ctrllimited="true" ctrlrange="-1.0 1.0" joint="agent1/ankle_7" gear="150" class="agent1" />
    <motor ctrllimited="true" ctrlrange="-1.0 1.0" joint="agent1/hip_8" gear="150" class="agent1" />
    <motor ctrllimited="true" ctrlrange="-1.0 1.0" joint="agent1/ankle_8" gear="150" class="agent1" />
  </actuator>

</mujoco>