<mujoco model="mutiagent_world">
  <compiler angle="degree" coordinate="local" inertiafromgeom="true" />
  
  <option integrator="RK4" timestep="0.003" solver="PGS" iterations="1000" />
  
  <default>
    <joint armature="1" damping="1" limited="true" />
  <default class="agent0"><joint armature="1" damping="1" limited="true" />
    <geom conaffinity="1" condim="3" density="5.0" friction="1 0.5 0.5" margin="0.01" rgba="0.5 0.25 0.25 1" />
    <motor ctrllimited="true" ctrlrange="-.4 .4" />
</default></default>
  <asset>
    <texture builtin="gradient" height="100" rgb1="1 1 1" rgb2="0 0 0" type="skybox" width="100" />
    <texture builtin="flat" height="1278" mark="cross" markrgb="1 1 1" name="texgeom" random="0.01" rgb1="0.8 0.6 0.4" rgb2="0.8 0.6 0.4" type="cube" width="127" />
    <texture builtin="checker" height="100" name="texplane" rgb1=".1 .1 .1" rgb2=".3 .3 0.3" type="2d" width="100" />
    <material name="MatPlane" reflectance="0.5" shininess="1" specular="1" texrepeat="60 60" texture="texplane" />
    <material name="geom" texture="texgeom" texuniform="true" />
  </asset>

  <worldbody>
    <light cutoff="100" diffuse="1 1 1" dir="-0 0 -1.3" directional="true" exponent="1" pos="0 0 1.3" specular=".1 .1 .1" />
    <geom contype="1" conaffinity="1" friction="1 .1 .1" condim="3" material="MatPlane" name="floor" pos="0 0 0" rgba="0.8 0.9 0.8 1" size="20 20 0.125" type="plane" />
    <geom fromto="4 -5 0  4 +5 0" name="rightgoal" rgba="0.6 0.0 0.0 1" size=".03" type="cylinder" />
    <geom fromto="-4 -5 0  -4 +5 0" name="leftgoal" rgba="0.6 0.0 0.0 1" size=".03" type="cylinder" />
  
  <body name="agent0/torso" pos="-1 0 0.75" euler="0 0 0">
  <geom name="agent0/torso_geom" pos="0 0 0" size="0.25" type="sphere" class="agent0" />
  <joint armature="0" damping="0" limited="false" margin="0.01" name="agent0/root" pos="0 0 0" range="-30 30" type="free" />
  <body name="agent0/front_left_leg" pos="0 0 0">
    <geom fromto="0.0 0.0 0.0 0.2 0.2 0.0" name="agent0/aux_1_geom" size="0.08" type="capsule" class="agent0" />
    <body name="agent0/aux_1" pos="0.2 0.2 0">
      <joint axis="0 0 1" name="agent0/hip_1" pos="0.0 0.0 0.0" range="-30 30" type="hinge" />
      <geom fromto="0.0 0.0 0.0 0.2 0.2 0.0" name="agent0/left_leg_geom" size="0.08" type="capsule" class="agent0" />
      <body pos="0.2 0.2 0" name="agent0/anon8577843436">
        <joint axis="-1 1 0" name="agent0/ankle_1" pos="0.0 0.0 0.0" range="30 70" type="hinge" />
        <geom fromto="0.0 0.0 0.0 0.4 0.4 0.0" name="agent0/left_ankle_geom" size="0.08" type="capsule" class="agent0" />
      </body>
    </body>
  </body>
  <body name="agent0/front_right_leg" pos="0 0 0">
    <geom fromto="0.0 0.0 0.0 -0.2 0.2 0.0" name="agent0/aux_2_geom" size="0.08" type="capsule" class="agent0" />
    <body name="agent0/aux_2" pos="-0.2 0.2 0">
      <joint axis="0 0 1" name="agent0/hip_2" pos="0.0 0.0 0.0" range="-30 30" type="hinge" />
      <geom fromto="0.0 0.0 0.0 -0.2 0.2 0.0" name="agent0/right_leg_geom" size="0.08" type="capsule" class="agent0" />
      <body pos="-0.2 0.2 0" name="agent0/anon4005303369">
        <joint axis="1 1 0" name="agent0/ankle_2" pos="0.0 0.0 0.0" range="-70 -30" type="hinge" />
        <geom fromto="0.0 0.0 0.0 -0.4 0.4 0.0" name="agent0/right_ankle_geom" size="0.08" type="capsule" class="agent0" />
      </body>
    </body>
  </body>
  <body name="agent0/back_leg" pos="0 0 0">
    <geom fromto="0.0 0.0 0.0 -0.2 -0.2 0.0" name="agent0/aux_3_geom" size="0.08" type="capsule" class="agent0" />
    <body name="agent0/aux_3" pos="-0.2 -0.2 0">
      <joint axis="0 0 1" name="agent0/hip_3" pos="0.0 0.0 0.0" range="-30 30" type="hinge" />
      <geom fromto="0.0 0.0 0.0 -0.2 -0.2 0.0" name="agent0/back_leg_geom" size="0.08" type="capsule" class="agent0" />
      <body pos="-0.2 -0.2 0" name="agent0/anon1703301250">
        <joint axis="-1 1 0" name="agent0/ankle_3" pos="0.0 0.0 0.0" range="-70 -30" type="hinge" />
        <geom fromto="0.0 0.0 0.0 -0.4 -0.4 0.0" name="agent0/third_ankle_geom" size="0.08" type="capsule" class="agent0" />
      </body>
    </body>
  </body>
  <body name="agent0/right_back_leg" pos="0 0 0">
    <geom fromto="0.0 0.0 0.0 0.2 -0.2 0.0" name="agent0/aux_4_geom" size="0.08" type="capsule" class="agent0" />
    <body name="agent0/aux_4" pos="0.2 -0.2 0">
      <joint axis="0 0 1" name="agent0/hip_4" pos="0.0 0.0 0.0" range="-30 30" type="hinge" />
      <geom fromto="0.0 0.0 0.0 0.2 -0.2 0.0" name="agent0/rightback_leg_geom" size="0.08" type="capsule" class="agent0" />
      <body pos="0.2 -0.2 0" name="agent0/anon1666063944">
        <joint axis="1 1 0" name="agent0/ankle_4" pos="0.0 0.0 0.0" range="30 70" type="hinge" />
        <geom fromto="0.0 0.0 0.0 0.4 -0.4 0.0" name="agent0/fourth_ankle_geom" size="0.08" type="capsule" class="agent0" />
      </body>
    </body>
  </body>
</body>

</worldbody>
<actuator>
  <motor ctrllimited="true" ctrlrange="-1.0 1.0" joint="agent0/hip_4" gear="150" class="agent0" />
  <motor ctrllimited="true" ctrlrange="-1.0 1.0" joint="agent0/ankle_4" gear="150" class="agent0" />
  <motor ctrllimited="true" ctrlrange="-1.0 1.0" joint="agent0/hip_1" gear="150" class="agent0" />
  <motor ctrllimited="true" ctrlrange="-1.0 1.0" joint="agent0/ankle_1" gear="150" class="agent0" />
  <motor ctrllimited="true" ctrlrange="-1.0 1.0" joint="agent0/hip_2" gear="150" class="agent0" />
  <motor ctrllimited="true" ctrlrange="-1.0 1.0" joint="agent0/ankle_2" gear="150" class="agent0" />
  <motor ctrllimited="true" ctrlrange="-1.0 1.0" joint="agent0/hip_3" gear="150" class="agent0" />
  <motor ctrllimited="true" ctrlrange="-1.0 1.0" joint="agent0/ankle_3" gear="150" class="agent0" />
</actuator>

</mujoco>